{
  "Header": {
    "Original": "CVE-2021-3428 (A flaw was found in the Linux kernel. A denial of service problem is i ...)",
    "Line": 161582,
    "ID": "CVE-2021-3428",
    "Description": "(A flaw was found in the Linux kernel. A denial of service problem is i ...)"
  },
  "Annotations": [
    {
      "Original": "{DLA-2689-1 DLA-2610-1}",
      "Line": 161583,
      "Type": "xref",
      "Bugs": [
        "DLA-2689-1",
        "DLA-2610-1"
      ]
    },
    {
      "Original": "- linux 5.8.7-1",
      "Line": 161584,
      "Type": "package",
      "Package": "linux",
      "Kind": "fixed",
      "Version": "5.8.7-1"
    },
    {
      "Original": "[buster] - linux 4.19.181-1",
      "Line": 161585,
      "Type": "package",
      "Release": "buster",
      "Package": "linux",
      "Kind": "fixed",
      "Version": "4.19.181-1"
    },
    {
      "Original": "NOTE: https://bugzilla.redhat.com/show_bug.cgi?id=1936786",
      "Line": 161586,
      "Type": "NOTE",
      "Description": "https://bugzilla.redhat.com/show_bug.cgi?id=1936786"
    },
    {
      "Original": "NOTE: https://www.openwall.com/lists/oss-security/2021/03/17/1",
      "Line": 161587,
      "Type": "NOTE",
      "Description": "https://www.openwall.com/lists/oss-security/2021/03/17/1"
    },
    {
      "Original": "NOTE: https://bugzilla.suse.com/show_bug.cgi?id=1173485",
      "Line": 161588,
      "Type": "NOTE",
      "Description": "https://bugzilla.suse.com/show_bug.cgi?id=1173485"
    }
  ]
}